Workbook

Sheet 1. Parámetros
A1: PARÁMETROS Y SUPUESTOS DEL MODELO (celdas amarillas = editables)
A2: Fuente base: Ley de Presupuestos 2026, Partida 21, Cap. 02 FOSIS. Calibrar multiplicadores con Transparencia Activa o EUS.
A4: Parámetro | B4: Valor | C4: Unidad | D4: Fuente / Comentario
A5: Costo promedio anual por cupo — Programa 01 | B5: =ROUND(19617274/613,0) | C5: miles $/año | D5: Subt.21 P01 / dotación máx. 613
A6: Costo promedio anual por cupo — Programa 03 | B6: =ROUND(2023577/72,0) | C6: miles $/año | D6: Subt.21 P03 / dotación máx. 72
A7: Costo promedio anual por cupo — Programa 04 | B7: =ROUND(7011685/286,0) | C7: miles $/año | D7: Subt.21 P04 / dotación máx. 286
A8: Costo promedio anual por cupo — INSTITUCIONAL | B8: =ROUND(28652536/971,0) | C8: miles $/año | D8: Subt.21 total / dotación máx. total
A9: Costo promedio mensual por cupo — INSTITUCIONAL | B9: =ROUND(B8/12,0) | C9: miles $/mes | D9: Derivado
A11: MULTIPLICADORES POR CATEGORÍA (supuestos editables — calibrar con EUS / Transparencia)
A12: Categoría de cargo | B12: Multiplicador | C12: Racional del supuesto
A13: Conducción (DR, Director Ejecutivo, Subdirector) | B13: 1.8 | C13: Grados 1C–4 + asignaciones de dirección; muy por sobre el promedio
A14: Jefatura / Encargado | B14: 1.4 | C14: Grados 5–12 con funciones directivas o encargadurías
A15: Soporte y especialización (profesionales) | B15: 1 | C15: En torno al promedio institucional
A16: Ejecutor de programa | B16: 0.8 | C16: Grados 16–19, mayoritariamente tipo 04/programa
A18: Los multiplicadores son supuestos de trabajo, NO cifras oficiales. Reemplazar por costos reales cuando se baje la remuneración bruta de Transparencia Activa.

Sheet 2. Presupuesto Ley 2026
A1: PRESUPUESTO FOSIS 2026 — LEY N° 21.796 (Partida 21, Capítulo 02) — miles de $
A3: Programa presupuestario | B3: Total programa | C3: Subt. 21 Personal | D3: Subt. 22 ByS | E3: Dotación máxima | F3: Honorarios autorizados (N°) | G3: Honorarios (miles $) | H3: Glosas clave
A4: 01 — FOSIS (operación institucional) | B4: 25103296 | C4: 19617274 | D4: 3928250 | E4: 613 | F4: 9 | G4: 141253 | H4: G.02: dot. máx 613, HH.EE. $37.094, viáticos $155.677+$903, func. críticas 17 pers./$172.186; G.01: 46 vehículos; Subt.29 informática $724.305; Innova FOSIS $734.552
A5: 03 — Generación de Ingresos Autónomos | B5: 35727313 | C5: 2023577 | D5: 166491 | E5: 72 | F5: 20 | G5: 380548 | H5: G.01: dot. máx 72, viáticos $12.058; Subt.33: Emprendamos $10.994.141, Emprendamos Semilla $21.512.084 (≥17.604 usuarios, G.06), Microcrédito $1.031.000; G.04: asignación regional vía GORE/Consejos
A6: 04 — Acompañamiento Familiar y Comunitario | B6: 51611834 | C6: 7011685 | D6: 92734 | E6: 286 | F6: 113 | G6: 2304729 | H6: G.01: dot. máx 286, 18 conv. pers. nat. ($287.966); G.04: 64 AT Habitabilidad ($1.377.015); G.05: 31 AT ASAL ($639.748); Subt.24: Acomp. Familiar $26.496.700, Habitabilidad $14.704.626; Subt.33: Comunidades Solidarias $1.226.787
A7: TOTAL FOSIS | B7: =SUM(B4:B6) | C7: =SUM(C4:C6) | D7: =SUM(D4:D6) | E7: =SUM(E4:E6) | F7: =SUM(F4:F6) | G7: =SUM(G4:G6)
A9: Ingresos por transferencia desde Subsecretaría de Servicios Sociales (Prog. 05 IEF/Chile Solidario): $43.280.618 corrientes (P04) + $17.024.706 capital (P03).
A10: Fuente: articles-406493_doc_pdf.pdf, págs. 1026–1031 del PDF. Honorarios P04 = 18 + 64 + 31 = 113 personas.

Sheet 3. Autorizado vs Real
A1: DOTACIÓN AUTORIZADA (LEY) vs. DOTACIÓN REAL (NÓMINA MAYO 2026)
A3: Concepto | B3: Autorizado Ley 2026 | C3: Real nómina may-2026 | D3: Holgura / Diferencia | E3: Lectura
A4: Dotación (planta + contrata) | B4: 971 | C4: 900 | D4: =B4-C4 | E4: Holgura de 71 cupos ≈ las 68 vacantes del Dashboard: el financiamiento existe; la restricción es la Circular N°12
A5: Honorarios (convenios pers. naturales) | B5: 142 | C5: 139 | D5: =B5-C5 | E5: Calza el desglose: 64 AT Habitabilidad ↔ 68 'Honorarios Habitabilidad'; 31 AT ASAL ↔ 33 'Autoconsumo'
A6: Total personas | B6: =B4+B5 | C6: =C4+C5 | D6: =B6-C6 | E6: Nómina total: 1.039
A8: DETALLE REAL POR CALIDAD JURÍDICA (nómina)
A9: Calidad jurídica | B9: N | C9: %
A10: Contrata | B10: 887 | C10: =B10/1039
A11: Planta | B11: 13 | C11: =B11/1039
A12: Honorarios | B12: 139 | C12: =B12/1039
A15: La dotación máxima legal NO incluye honorarios (se autorizan aparte por glosa). Los 4 directivos ADP y los 88 cupos de funciones directivas operan dentro de la dotación.

Sheet 4. Simulación 41 vacantes
A1: COSTEO DE LAS 41 VACANTES MARCADAS 'SÍ PROVEER' (Dashboard de Dotación, mayo 2026)
A2: Costo estimado = costo promedio institucional por cupo ('1. Parámetros'!B7) × multiplicador de categoría. Supuesto editable; reemplazar por remuneración real de Transparencia Activa.
A4: Región / Unidad | B4: Cargo vacante | C4: Grado | D4: Categoría | E4: Multiplicador | F4: Costo anual estimado (miles $) | G4: Costo mensual estimado (miles $)
A5: Tarapacá | B5: Director/a Regional | C5: 4 | D5: Conducción | E5: ='1. Parámetros'!B13 | F5: =ROUND('1. Parámetros'!B8*E5,0) | G5: =ROUND(F5/12,0)
A6: Tarapacá | B6: Encargado/a de Control de Gestión Regional | C6: 12 | D6: Jefatura/Enc. | E6: ='1. Parámetros'!B14 | F6: =ROUND('1. Parámetros'!B8*E6,0) | G6: =ROUND(F6/12,0)
A7: Antofagasta | B7: Director/a Regional | C7: 4 | D7: Conducción | E7: ='1. Parámetros'!B13 | F7: =ROUND('1. Parámetros'!B8*E7,0) | G7: =ROUND(F7/12,0)
A8: Atacama | B8: Director/a Regional | C8: 4 | D8: Conducción | E8: ='1. Parámetros'!B13 | F8: =ROUND('1. Parámetros'!B8*E8,0) | G8: =ROUND(F8/12,0)
A9: Coquimbo | B9: Director/a Regional | C9: 4 | D9: Conducción | E9: ='1. Parámetros'!B13 | F9: =ROUND('1. Parámetros'!B8*E9,0) | G9: =ROUND(F9/12,0)
A10: Valparaíso | B10: Director/a Regional | C10: 4 | D10: Conducción | E10: ='1. Parámetros'!B13 | F10: =ROUND('1. Parámetros'!B8*E10,0) | G10: =ROUND(F10/12,0)
A11: O'Higgins | B11: Director/a Regional | C11: 4 | D11: Conducción | E11: ='1. Parámetros'!B13 | F11: =ROUND('1. Parámetros'!B8*E11,0) | G11: =ROUND(F11/12,0)
A12: Maule | B12: Director/a Regional | C12: 4 | D12: Conducción | E12: ='1. Parámetros'!B13 | F12: =ROUND('1. Parámetros'!B8*E12,0) | G12: =ROUND(F12/12,0)
A13: Biobío | B13: Director/a Regional | C13: 4 | D13: Conducción | E13: ='1. Parámetros'!B13 | F13: =ROUND('1. Parámetros'!B8*E13,0) | G13: =ROUND(F13/12,0)
A14: Araucanía | B14: Director/a Regional | C14: 4 | D14: Conducción | E14: ='1. Parámetros'!B13 | F14: =ROUND('1. Parámetros'!B8*E14,0) | G14: =ROUND(F14/12,0)
A15: Araucanía | B15: Asistente Administrativo (Personas) | C15: 18 | D15: Soporte | E15: ='1. Parámetros'!B15 | F15: =ROUND('1. Parámetros'!B8*E15,0) | G15: =ROUND(F15/12,0)
A16: Los Lagos | B16: Director/a Regional | C16: 4 | D16: Conducción | E16: ='1. Parámetros'!B13 | F16: =ROUND('1. Parámetros'!B8*E16,0) | G16: =ROUND(F16/12,0)
A17: Los Lagos | B17: Encargado/a Regional de Programas | C17: 12 | D17: Jefatura/Enc. | E17: ='1. Parámetros'!B14 | F17: =ROUND('1. Parámetros'!B8*E17,0) | G17: =ROUND(F17/12,0)
A18: Los Lagos | B18: Apoyo Provincial SSyOO (movilidad Araucanía→Los Lagos) | C18: 17 | D18: Ejecutor | E18: ='1. Parámetros'!B16 | F18: =ROUND('1. Parámetros'!B8*E18,0) | G18: =ROUND(F18/12,0)
A19: Los Lagos | B19: Gestor/a Familiar Programa Eje | C19: 17 | D19: Ejecutor | E19: ='1. Parámetros'!B16 | F19: =ROUND('1. Parámetros'!B8*E19,0) | G19: =ROUND(F19/12,0)
A20: Aysén | B20: Director/a Regional | C20: 4 | D20: Conducción | E20: ='1. Parámetros'!B13 | F20: =ROUND('1. Parámetros'!B8*E20,0) | G20: =ROUND(F20/12,0)
A21: Aysén | B21: Gestor/a Familiar Eje (evaluar transformar a Prof. Rendiciones) | C21: 17 | D21: Ejecutor | E21: ='1. Parámetros'!B16 | F21: =ROUND('1. Parámetros'!B8*E21,0) | G21: =ROUND(F21/12,0)
A22: Magallanes | B22: Director/a Regional | C22: 4 | D22: Conducción | E22: ='1. Parámetros'!B13 | F22: =ROUND('1. Parámetros'!B8*E22,0) | G22: =ROUND(F22/12,0)
A23: DR Metropolitana | B23: Director/a Regional | C23: 4 | D23: Conducción | E23: ='1. Parámetros'!B13 | F23: =ROUND('1. Parámetros'!B8*E23,0) | G23: =ROUND(F23/12,0)
A24: DR Metropolitana | B24: Asesor/a Jurídico Regional | C24: 8 | D24: Soporte | E24: ='1. Parámetros'!B15 | F24: =ROUND('1. Parámetros'!B8*E24,0) | G24: =ROUND(F24/12,0)
A25: DR Metropolitana | B25: Profesional de Gestión y Análisis | C25: 11 | D25: Soporte | E25: ='1. Parámetros'!B15 | F25: =ROUND('1. Parámetros'!B8*E25,0) | G25: =ROUND(F25/12,0)
A26: DR Metropolitana | B26: Gestor/a Familiar Programa Eje | C26: 17 | D26: Ejecutor | E26: ='1. Parámetros'!B16 | F26: =ROUND('1. Parámetros'!B8*E26,0) | G26: =ROUND(F26/12,0)
A27: Los Ríos | B27: Director/a Regional | C27: 4 | D27: Conducción | E27: ='1. Parámetros'!B13 | F27: =ROUND('1. Parámetros'!B8*E27,0) | G27: =ROUND(F27/12,0)
A28: Los Ríos | B28: Profesional Regional de Rendiciones | C28: 18 | D28: Soporte | E28: ='1. Parámetros'!B15 | F28: =ROUND('1. Parámetros'!B8*E28,0) | G28: =ROUND(F28/12,0)
A29: Arica y Parinacota | B29: Director/a Regional | C29: 4 | D29: Conducción | E29: ='1. Parámetros'!B13 | F29: =ROUND('1. Parámetros'!B8*E29,0) | G29: =ROUND(F29/12,0)
A30: Ñuble | B30: Director/a Regional | C30: 4 | D30: Conducción | E30: ='1. Parámetros'!B13 | F30: =ROUND('1. Parámetros'!B8*E30,0) | G30: =ROUND(F30/12,0)
A31: Ñuble | B31: Encargado/a de Personas Regional | C31: 12 | D31: Jefatura/Enc. | E31: ='1. Parámetros'!B14 | F31: =ROUND('1. Parámetros'!B8*E31,0) | G31: =ROUND(F31/12,0)
A32: Ñuble | B32: Analista Técnico Contable | C32: 16 | D32: Soporte | E32: ='1. Parámetros'!B15 | F32: =ROUND('1. Parámetros'!B8*E32,0) | G32: =ROUND(F32/12,0)
A33: Ñuble | B33: Apoyo Técnico Regional SSyOO | C33: 17 | D33: Soporte | E33: ='1. Parámetros'!B15 | F33: =ROUND('1. Parámetros'!B8*E33,0) | G33: =ROUND(F33/12,0)
A34: Dirección Nacional | B34: Jefe/a de Gabinete | C34: 4 | D34: Jefatura/Enc. | E34: ='1. Parámetros'!B14 | F34: =ROUND('1. Parámetros'!B8*E34,0) | G34: =ROUND(F34/12,0)
A35: Dirección Nacional | B35: Encargado/a de Innovación Central | C35: 7 | D35: Jefatura/Enc. | E35: ='1. Parámetros'!B14 | F35: =ROUND('1. Parámetros'!B8*E35,0) | G35: =ROUND(F35/12,0)
A36: Dirección Nacional | B36: Asistente Administrativo Transversal | C36: 10 | D36: Soporte | E36: ='1. Parámetros'!B15 | F36: =ROUND('1. Parámetros'!B8*E36,0) | G36: =ROUND(F36/12,0)
A37: Dirección Nacional | B37: Director/a Ejecutivo/a | C37: 1C | D37: Conducción | E37: ='1. Parámetros'!B13 | F37: =ROUND('1. Parámetros'!B8*E37,0) | G37: =ROUND(F37/12,0)
A38: Dirección Nacional | B38: Jefe/a Departamento de Presupuesto | C38: 8 | D38: Jefatura/Enc. | E38: ='1. Parámetros'!B14 | F38: =ROUND('1. Parámetros'!B8*E38,0) | G38: =ROUND(F38/12,0)
A39: Dirección Nacional | B39: Profesional Sistemas Informáticos | C39: 12 | D39: Soporte | E39: ='1. Parámetros'!B15 | F39: =ROUND('1. Parámetros'!B8*E39,0) | G39: =ROUND(F39/12,0)
A40: Dirección Nacional | B40: Profesional Sistemas Informáticos (Ciberseguridad) | C40: 12 | D40: Soporte | E40: ='1. Parámetros'!B15 | F40: =ROUND('1. Parámetros'!B8*E40,0) | G40: =ROUND(F40/12,0)
A41: Dirección Nacional | B41: Profesional Sistemas Informáticos | C41: 14 | D41: Soporte | E41: ='1. Parámetros'!B15 | F41: =ROUND('1. Parámetros'!B8*E41,0) | G41: =ROUND(F41/12,0)
...

Sheet 5. Resumen
A1: RESUMEN EJECUTIVO DEL COSTEO
A3: Categoría | B3: N° vacantes 'SÍ' | C3: Costo anual estimado (miles $)
A4: Conducción | B4: =COUNTIF('4. Simulación 41 vacantes'!D5:D45,"Conducción") | C4: =SUMIF('4. Simulación 41 vacantes'!D5:D45,"Conducción",'4. Simulación 41 vacantes'!F5:F45)
A5: Jefatura/Enc. | B5: =COUNTIF('4. Simulación 41 vacantes'!D5:D45,"Jefatura/Enc.") | C5: =SUMIF('4. Simulación 41 vacantes'!D5:D45,"Jefatura/Enc.",'4. Simulación 41 vacantes'!F5:F45)
A6: Soporte | B6: =COUNTIF('4. Simulación 41 vacantes'!D5:D45,"Soporte") | C6: =SUMIF('4. Simulación 41 vacantes'!D5:D45,"Soporte",'4. Simulación 41 vacantes'!F5:F45)
A7: Ejecutor | B7: =COUNTIF('4. Simulación 41 vacantes'!D5:D45,"Ejecutor") | C7: =SUMIF('4. Simulación 41 vacantes'!D5:D45,"Ejecutor",'4. Simulación 41 vacantes'!F5:F45)
A8: TOTAL | B8: =SUM(B4:B7) | C8: =SUM(C4:C7)
A11: Mensajes para la presentación: (1) la plata existe en la Ley — la restricción es la Circular N°12; (2) los 16 DR ya están financiados vía funciones directivas, su registro nominal es costo ~$0; (3) priorizar ejecutores en regiones con déficit (Ñuble, Aysén, Los Ríos) maximiza impacto por peso gastado.
A12: Modelo elaborado por DDO — junio 2026. Supuestos editables en hoja '1. Parámetros'. Calibrar con Transparencia Activa antes de uso oficial.
